Error occurred at: 2025-09-30 14:50:21
Error: 'run_id'
Traceback:
Traceback (most recent call last):
  File "C:\Users\Ethan\code\2.156ps1\multi_node_recursive.py", line 1235, in <module>
    results = multi_node_recursive_optimization()
  File "C:\Users\Ethan\code\2.156ps1\multi_node_recursive.py", line 1056, in multi_node_recursive_optimization
    ax.set_title(f'{epoch["num_nodes"]} nodes, Run {epoch["run_id"]}\n{len(F)} pts, HV: {hv_value:.3f}', fontsize=10)
KeyError: 'run_id'
